2019-09-14 11:53:28,319:DEBUG:certbot.main:certbot version: 0.37.1
2019-09-14 11:53:28,319:DEBUG:certbot.main:Arguments: ['--config-dir', '/Users/minh/Desktop/awesome/awesome-system/k8s/00-generic/certs-anhminhltd.com', '--work-dir', '/Users/minh/Desktop/awesome/awesome-system/k8s/00-generic/certs-anhminhltd.com', '--logs-dir', '/Users/minh/Desktop/awesome/awesome-system/k8s/00-generic/certs-anhminhltd.com']
2019-09-14 11:53:28,320:DEBUG:certbot.main:Discovered plugins: PluginsRegistry(PluginEntryPoint#apache,PluginEntryPoint#manual,PluginEntryPoint#nginx,PluginEntryPoint#null,PluginEntryPoint#standalone,PluginEntryPoint#webroot)
2019-09-14 11:53:28,354:DEBUG:certbot.log:Root logging level set at 20
2019-09-14 11:53:28,354:INFO:certbot.log:Saving debug log to /Users/minh/Desktop/awesome/awesome-system/k8s/00-generic/certs-anhminhltd.com/letsencrypt.log
2019-09-14 11:53:28,358:WARNING:certbot.renewal:
Traceback (most recent call last):
  File "/usr/local/Cellar/certbot/0.37.1_1/libexec/lib/python3.7/site-packages/certbot/renewal.py", line 64, in _reconstitute
    renewal_candidate = storage.RenewableCert(full_path, config)
  File "/usr/local/Cellar/certbot/0.37.1_1/libexec/lib/python3.7/site-packages/certbot/storage.py", line 466, in __init__
    self._check_symlinks()
  File "/usr/local/Cellar/certbot/0.37.1_1/libexec/lib/python3.7/site-packages/certbot/storage.py", line 524, in _check_symlinks
    "expected {0} to be a symlink".format(link))
certbot.errors.CertStorageError: expected /Users/minh/Desktop/ezlife/awesome-system/k8s/00-generic/certs-anhminhltd.com/live/anhminhltd.com/cert.pem to be a symlink
2019-09-14 11:53:28,362:WARNING:certbot.renewal:Renewal configuration file /Users/minh/Desktop/awesome/awesome-system/k8s/00-generic/certs-anhminhltd.com/renewal/anhminhltd.com.conf is broken. Skipping.
2019-09-14 11:53:28,362:DEBUG:certbot.renewal:Traceback was:
Traceback (most recent call last):
  File "/usr/local/Cellar/certbot/0.37.1_1/libexec/lib/python3.7/site-packages/certbot/renewal.py", line 64, in _reconstitute
    renewal_candidate = storage.RenewableCert(full_path, config)
  File "/usr/local/Cellar/certbot/0.37.1_1/libexec/lib/python3.7/site-packages/certbot/storage.py", line 466, in __init__
    self._check_symlinks()
  File "/usr/local/Cellar/certbot/0.37.1_1/libexec/lib/python3.7/site-packages/certbot/storage.py", line 524, in _check_symlinks
    "expected {0} to be a symlink".format(link))
certbot.errors.CertStorageError: expected /Users/minh/Desktop/ezlife/awesome-system/k8s/00-generic/certs-anhminhltd.com/live/anhminhltd.com/cert.pem to be a symlink

2019-09-14 11:53:28,362:DEBUG:certbot.log:Exiting abnormally:
Traceback (most recent call last):
  File "/usr/local/bin/certbot", line 11, in <module>
    load_entry_point('certbot==0.37.1', 'console_scripts', 'certbot')()
  File "/usr/local/Cellar/certbot/0.37.1_1/libexec/lib/python3.7/site-packages/certbot/main.py", line 1378, in main
    return config.func(config, plugins)
  File "/usr/local/Cellar/certbot/0.37.1_1/libexec/lib/python3.7/site-packages/certbot/main.py", line 1287, in renew
    renewal.handle_renewal_request(config)
  File "/usr/local/Cellar/certbot/0.37.1_1/libexec/lib/python3.7/site-packages/certbot/renewal.py", line 474, in handle_renewal_request
    len(renew_failures), len(parse_failures)))
certbot.errors.Error: 0 renew failure(s), 1 parse failure(s)
